<sdf version='1.7'>
  <world name='default'>
    <light name='sun' type='directional'>
      <cast_shadows>1</cast_shadows>
      <pose>0 0 10 0 -0 0</pose>
      <diffuse>0.8 0.8 0.8 1</diffuse>
      <specular>0.2 0.2 0.2 1</specular>
      <attenuation>
        <range>1000</range>
        <constant>0.9</constant>
        <linear>0.01</linear>
        <quadratic>0.001</quadratic>
      </attenuation>
      <direction>-0.5 0.1 -0.9</direction>
      <spot>
        <inner_angle>0</inner_angle>
        <outer_angle>0</outer_angle>
        <falloff>0</falloff>
      </spot>
    </light>
    <model name='overhead_camera'>
      <static>1</static>
      <pose>0.75 0 1.5 0 1.87 0</pose>
      <link name='camera_link'>
        <sensor name='camera_sensor' type='camera'>
          <always_on>1</always_on>
          <update_rate>20</update_rate>
          <camera>
            <horizontal_fov>0.875</horizontal_fov>
            <image>
              <width>640</width>
              <height>480</height>
              <format>R8G8B8</format>
            </image>
            <clip>
              <near>0.1</near>
              <far>100</far>
            </clip>
          </camera>
          <visualize>1</visualize>
          <topic>/overhead_camera/image_raw</topic>
          <!-- Plugin para ROS2 -->
          <plugin name="gazebo_ros_camera" filename="libgazebo_ros_camera.so">
            <always_on>true</always_on>
            <update_rate>30</update_rate>
            <camera_name>overhead_camera</camera_name>
            <image_topic_name>image_raw</image_topic_name>
            <camera_info_topic_name>camera_info</camera_info_topic_name>
            <frame_name>overhead_camera_link</frame_name>
          </plugin>
        </sensor>
        <self_collide>0</self_collide>
        <enable_wind>0</enable_wind>
        <kinematic>0</kinematic>
      </link>
    </model>
    <plugin name='gazebo_ros_camera' filename='libgazebo_ros_camera.so'>
      <always_on>1</always_on>
      <update_rate>30</update_rate>
      <camera_name>overhead_camera</camera_name>
      <image_topic_name>image_raw</image_topic_name>
      <camera_info_topic_name>camera_info</camera_info_topic_name>
      <frame_name>overhead_camera_link</frame_name>
    </plugin>
    <model name='ground_plane'>
      <static>1</static>
      <link name='link'>
        <collision name='collision'>
          <geometry>
            <plane>
              <normal>0 0 1</normal>
              <size>100 100</size>
            </plane>
          </geometry>
          <surface>
            <friction>
              <ode>
                <mu>100</mu>
                <mu2>50</mu2>
              </ode>
              <torsional>
                <ode/>
              </torsional>
            </friction>
            <contact>
              <ode/>
            </contact>
            <bounce/>
          </surface>
          <max_contacts>10</max_contacts>
        </collision>
        <visual name='visual'>
          <cast_shadows>0</cast_shadows>
          <geometry>
            <plane>
              <normal>0 0 1</normal>
              <size>100 100</size>
            </plane>
          </geometry>
          <material>
            <script>
              <uri>file://media/materials/scripts/gazebo.material</uri>
              <name>Gazebo/Grey</name>
            </script>
          </material>
        </visual>
        <self_collide>0</self_collide>
        <enable_wind>0</enable_wind>
        <kinematic>0</kinematic>
      </link>
    </model>
    <gravity>0 0 -9.8</gravity>
    <magnetic_field>6e-06 2.3e-05 -4.2e-05</magnetic_field>
    <atmosphere type='adiabatic'/>
    <physics type='ode'>
      <max_step_size>0.001</max_step_size>
      <real_time_factor>1</real_time_factor>
      <real_time_update_rate>1000</real_time_update_rate>
    </physics>
    <scene>
      <ambient>0.4 0.4 0.4 1</ambient>
      <background>0.7 0.7 0.7 1</background>
      <shadows>1</shadows>
    </scene>
    <wind/>
    <spherical_coordinates>
      <surface_model>EARTH_WGS84</surface_model>
      <latitude_deg>0</latitude_deg>
      <longitude_deg>0</longitude_deg>
      <elevation>0</elevation>
      <heading_deg>0</heading_deg>
    </spherical_coordinates>
    <model name='Marker10'>
      <static>1</static>
      <link name='link'>
        <visual name='visual'>
          <geometry>
            <mesh>
              <uri>model://marker10/meshes/Marker10.dae</uri>
              <scale>1 1.5 1</scale>
            </mesh>
          </geometry>
        </visual>
        <self_collide>0</self_collide>
        <enable_wind>0</enable_wind>
        <kinematic>0</kinematic>
      </link>
      <pose>0.452934 0.217654 0 0 -0 0</pose>
    </model>
    <model name='Marker2'>
      <static>1</static>
      <link name='link'>
        <visual name='visual'>
          <geometry>
            <mesh>
              <uri>model://marker2/meshes/Marker2.dae</uri>
              <scale>0.4 0.4 0.4</scale>
            </mesh>
          </geometry>
        </visual>
        <self_collide>0</self_collide>
        <enable_wind>0</enable_wind>
        <kinematic>0</kinematic>
      </link>
      <pose>-1.276 -0.946359 0 0 -0 0</pose>
    </model>
    <model name='eurobot_cositas'>
      <static>1</static>
      <link name='wall_pos_x'>
        <pose>1.5 0 0.035 0 -0 0</pose>
        <collision name='col'>
          <geometry>
            <box>
              <size>0.022 2 0.07</size>
            </box>
          </geometry>
          <max_contacts>10</max_contacts>
          <surface>
            <contact>
              <ode/>
            </contact>
            <bounce/>
            <friction>
              <torsional>
                <ode/>
              </torsional>
              <ode/>
            </friction>
          </surface>
        </collision>
        <visual name='vis'>
          <geometry>
            <box>
              <size>0.022 2 0.07</size>
            </box>
          </geometry>
          <material>
            <ambient>0.2 0.2 0.2 1</ambient>
            <diffuse>0.4 0.4 0.4 1</diffuse>
          </material>
        </visual>
        <self_collide>0</self_collide>
        <enable_wind>0</enable_wind>
        <kinematic>0</kinematic>
      </link>
      <link name='wall_neg_x'>
        <pose>-1.5 0 0.035 0 -0 0</pose>
        <collision name='col'>
          <geometry>
            <box>
              <size>0.022 2 0.07</size>
            </box>
          </geometry>
          <max_contacts>10</max_contacts>
          <surface>
            <contact>
              <ode/>
            </contact>
            <bounce/>
            <friction>
              <torsional>
                <ode/>
              </torsional>
              <ode/>
            </friction>
          </surface>
        </collision>
        <visual name='vis'>
          <geometry>
            <box>
              <size>0.022 2 0.07</size>
            </box>
          </geometry>
        </visual>
        <self_collide>0</self_collide>
        <enable_wind>0</enable_wind>
        <kinematic>0</kinematic>
      </link>
      <link name='wall_pos_y'>
        <pose>0 1 0.035 0 -0 0</pose>
        <collision name='col'>
          <geometry>
            <box>
              <size>3 0.022 0.07</size>
            </box>
          </geometry>
          <max_contacts>10</max_contacts>
          <surface>
            <contact>
              <ode/>
            </contact>
            <bounce/>
            <friction>
              <torsional>
                <ode/>
              </torsional>
              <ode/>
            </friction>
          </surface>
        </collision>
        <visual name='vis'>
          <geometry>
            <box>
              <size>3 0.022 0.07</size>
            </box>
          </geometry>
        </visual>
        <self_collide>0</self_collide>
        <enable_wind>0</enable_wind>
        <kinematic>0</kinematic>
      </link>
      <link name='wall_neg_y'>
        <pose>0 -1 0.035 0 -0 0</pose>
        <collision name='col'>
          <geometry>
            <box>
              <size>3 0.022 0.07</size>
            </box>
          </geometry>
          <max_contacts>10</max_contacts>
          <surface>
            <contact>
              <ode/>
            </contact>
            <bounce/>
            <friction>
              <torsional>
                <ode/>
              </torsional>
              <ode/>
            </friction>
          </surface>
        </collision>
        <visual name='vis'>
          <geometry>
            <box>
              <size>3 0.022 0.07</size>
            </box>
          </geometry>
        </visual>
        <self_collide>0</self_collide>
        <enable_wind>0</enable_wind>
        <kinematic>0</kinematic>
      </link>
      <pose>-0.07777 -0.280673 0 0 -0 0</pose>
    </model>
    <model name='Marker3'>
      <static>1</static>
      <link name='link'>
        <visual name='visual'>
          <geometry>
            <mesh>
              <uri>model://marker3/meshes/Marker3.dae</uri>
              <scale>0.4 0.4 0.4</scale>
            </mesh>
          </geometry>
        </visual>
        <self_collide>0</self_collide>
        <enable_wind>0</enable_wind>
        <kinematic>0</kinematic>
      </link>
      <pose>-0.046394 -0.618429 0 0 -0 0</pose>
    </model>
    <model name='turtlebot3_burger'>
      <pose>0.259019 -0.013939 0 0 -0 0</pose>
      <link name='base_footprint'>
        <self_collide>0</self_collide>
        <inertial>
          <pose>0 0 0 0 -0 0</pose>
          <inertia>
            <ixx>1</ixx>
            <ixy>0</ixy>
            <ixz>0</ixz>
            <iyy>1</iyy>
            <iyz>0</iyz>
            <izz>1</izz>
          </inertia>
          <mass>1</mass>
        </inertial>
        <enable_wind>0</enable_wind>
        <kinematic>0</kinematic>
      </link>
      <link name='base_link'>
        <inertial>
          <pose>-0.032 0 0.07 0 -0 0</pose>
          <inertia>
            <ixx>0.723974</ixx>
            <ixy>4.6864e-10</ixy>
            <ixz>-1.09526e-08</ixz>
            <iyy>0.723974</iyy>
            <iyz>2.85826e-09</iyz>
            <izz>0.65305</izz>
          </inertia>
          <mass>0.825735</mass>
        </inertial>
        <collision name='base_collision'>
          <pose>-0.032 0 0.07 0 -0 0</pose>
          <geometry>
            <box>
              <size>0.14 0.14 0.14</size>
            </box>
          </geometry>
          <max_contacts>10</max_contacts>
          <surface>
            <contact>
              <ode/>
            </contact>
            <bounce/>
            <friction>
              <torsional>
                <ode/>
              </torsional>
              <ode/>
            </friction>
          </surface>
        </collision>
        <visual name='base_visual'>
          <pose>-0.032 0 0 0 -0 0</pose>
          <geometry>
            <mesh>
              <uri>model://turtlebot3_burger/meshes/burger_base.dae</uri>
              <scale>0.001 0.001 0.001</scale>
            </mesh>
          </geometry>
        </visual>
        <self_collide>0</self_collide>
        <enable_wind>0</enable_wind>
        <kinematic>0</kinematic>
      </link>
      <link name='imu_link'>
        <sensor name='tb3_imu' type='imu'>
          <always_on>1</always_on>
          <update_rate>200</update_rate>
          <imu>
            <angular_velocity>
              <x>
                <noise type='gaussian'>
                  <mean>0</mean>
                  <stddev>0.0002</stddev>
                </noise>
              </x>
              <y>
                <noise type='gaussian'>
                  <mean>0</mean>
                  <stddev>0.0002</stddev>
                </noise>
              </y>
              <z>
                <noise type='gaussian'>
                  <mean>0</mean>
                  <stddev>0.0002</stddev>
                </noise>
              </z>
            </angular_velocity>
            <linear_acceleration>
              <x>
                <noise type='gaussian'>
                  <mean>0</mean>
                  <stddev>0.017</stddev>
                </noise>
              </x>
              <y>
                <noise type='gaussian'>
                  <mean>0</mean>
                  <stddev>0.017</stddev>
                </noise>
              </y>
              <z>
                <noise type='gaussian'>
                  <mean>0</mean>
                  <stddev>0.017</stddev>
                </noise>
              </z>
            </linear_acceleration>
            <angular_velocity/>
            <linear_acceleration/>
          </imu>
          <plugin name='turtlebot3_imu' filename='libgazebo_ros_imu_sensor.so'>
            <ros>
              <remapping>~/out:=imu</remapping>
            </ros>
          </plugin>
        </sensor>
        <self_collide>0</self_collide>
        <inertial>
          <pose>0 0 0 0 -0 0</pose>
          <inertia>
            <ixx>1</ixx>
            <ixy>0</ixy>
            <ixz>0</ixz>
            <iyy>1</iyy>
            <iyz>0</iyz>
            <izz>1</izz>
          </inertia>
          <mass>1</mass>
        </inertial>
        <enable_wind>0</enable_wind>
        <kinematic>0</kinematic>
      </link>
      <link name='base_scan'>
        <inertial>
          <pose>-0.02 0 0.161 0 -0 0</pose>
          <inertia>
            <ixx>0.001</ixx>
            <ixy>0</ixy>
            <ixz>0</ixz>
            <iyy>0.001</iyy>
            <iyz>0</iyz>
            <izz>0.001</izz>
          </inertia>
          <mass>0.114</mass>
        </inertial>
        <collision name='lidar_sensor_collision'>
          <pose>-0.02 0 0.161 0 -0 0</pose>
          <geometry>
            <cylinder>
              <radius>0.0508</radius>
              <length>0.055</length>
            </cylinder>
          </geometry>
          <max_contacts>10</max_contacts>
          <surface>
            <contact>
              <ode/>
            </contact>
            <bounce/>
            <friction>
              <torsional>
                <ode/>
              </torsional>
              <ode/>
            </friction>
          </surface>
        </collision>
        <visual name='lidar_sensor_visual'>
          <pose>-0.032 0 0.171 0 -0 0</pose>
          <geometry>
            <mesh>
              <uri>model://turtlebot3_burger/meshes/lds.dae</uri>
              <scale>0.001 0.001 0.001</scale>
            </mesh>
          </geometry>
        </visual>
        <sensor name='hls_lfcd_lds' type='ray'>
          <always_on>1</always_on>
          <visualize>1</visualize>
          <pose>-0.032 0 0.171 0 -0 0</pose>
          <update_rate>5</update_rate>
          <ray>
            <scan>
              <horizontal>
                <samples>360</samples>
                <resolution>1</resolution>
                <min_angle>0</min_angle>
                <max_angle>6.28</max_angle>
              </horizontal>
              <vertical>
                <samples>1</samples>
                <min_angle>0</min_angle>
                <max_angle>0</max_angle>
              </vertical>
            </scan>
            <range>
              <min>0.12</min>
              <max>3.5</max>
              <resolution>0.015</resolution>
            </range>
            <noise>
              <type>gaussian</type>
              <mean>0</mean>
              <stddev>0.01</stddev>
            </noise>
          </ray>
          <plugin name='turtlebot3_laserscan' filename='libgazebo_ros_ray_sensor.so'>
            <ros>
              <remapping>~/out:=scan</remapping>
            </ros>
            <output_type>sensor_msgs/LaserScan</output_type>
            <frame_name>base_scan</frame_name>
          </plugin>
        </sensor>
        <self_collide>0</self_collide>
        <enable_wind>0</enable_wind>
        <kinematic>0</kinematic>
      </link>
      <link name='wheel_left_link'>
        <inertial>
          <pose>0 0.08 0.023 -1.57 0 0</pose>
          <inertia>
            <ixx>0.00181582</ixx>
            <ixy>-9.3392e-12</ixy>
            <ixz>1.04909e-11</ixz>
            <iyy>0.00329221</iyy>
            <iyz>5.75694e-11</iyz>
            <izz>0.00181582</izz>
          </inertia>
          <mass>0.0284989</mass>
        </inertial>
        <collision name='wheel_left_collision'>
          <pose>0 0.08 0.023 -1.57 0 0</pose>
          <geometry>
            <cylinder>
              <radius>0.033</radius>
              <length>0.018</length>
            </cylinder>
          </geometry>
          <surface>
            <friction>
              <ode>
                <mu>100000</mu>
                <mu2>100000</mu2>
                <fdir1>0 0 0</fdir1>
                <slip1>0</slip1>
                <slip2>0</slip2>
              </ode>
              <torsional>
                <ode/>
              </torsional>
            </friction>
            <contact>
              <ode>
                <soft_cfm>0</soft_cfm>
                <soft_erp>0.2</soft_erp>
                <kp>100000</kp>
                <kd>1</kd>
                <max_vel>0.01</max_vel>
                <min_depth>0.001</min_depth>
              </ode>
            </contact>
            <bounce/>
          </surface>
          <max_contacts>10</max_contacts>
        </collision>
        <visual name='wheel_left_visual'>
          <pose>0 0.08 0.023 0 -0 0</pose>
          <geometry>
            <mesh>
              <uri>model://turtlebot3_burger/meshes/tire.dae</uri>
              <scale>0.001 0.001 0.001</scale>
            </mesh>
          </geometry>
        </visual>
        <self_collide>0</self_collide>
        <enable_wind>0</enable_wind>
        <kinematic>0</kinematic>
      </link>
      <link name='wheel_right_link'>
        <inertial>
          <pose>0 -0.08 0.023 -1.57 0 0</pose>
          <inertia>
            <ixx>0.00181582</ixx>
            <ixy>-9.3392e-12</ixy>
            <ixz>1.04909e-11</ixz>
            <iyy>0.00329221</iyy>
            <iyz>5.75694e-11</iyz>
            <izz>0.00181582</izz>
          </inertia>
          <mass>0.0284989</mass>
        </inertial>
        <collision name='wheel_right_collision'>
          <pose>0 -0.08 0.023 -1.57 0 0</pose>
          <geometry>
            <cylinder>
              <radius>0.033</radius>
              <length>0.018</length>
            </cylinder>
          </geometry>
          <surface>
            <friction>
              <ode>
                <mu>100000</mu>
                <mu2>100000</mu2>
                <fdir1>0 0 0</fdir1>
                <slip1>0</slip1>
                <slip2>0</slip2>
              </ode>
              <torsional>
                <ode/>
              </torsional>
            </friction>
            <contact>
              <ode>
                <soft_cfm>0</soft_cfm>
                <soft_erp>0.2</soft_erp>
                <kp>100000</kp>
                <kd>1</kd>
                <max_vel>0.01</max_vel>
                <min_depth>0.001</min_depth>
              </ode>
            </contact>
            <bounce/>
          </surface>
          <max_contacts>10</max_contacts>
        </collision>
        <visual name='wheel_right_visual'>
          <pose>0 -0.08 0.023 0 -0 0</pose>
          <geometry>
            <mesh>
              <uri>model://turtlebot3_burger/meshes/tire.dae</uri>
              <scale>0.001 0.001 0.001</scale>
            </mesh>
          </geometry>
        </visual>
        <self_collide>0</self_collide>
        <enable_wind>0</enable_wind>
        <kinematic>0</kinematic>
      </link>
      <link name='caster_back_link'>
        <pose>-0.081 0 -0.004 -1.57 0 0</pose>
        <inertial>
          <mass>0.005</mass>
          <inertia>
            <ixx>0.001</ixx>
            <ixy>0</ixy>
            <ixz>0</ixz>
            <iyy>0.001</iyy>
            <iyz>0</iyz>
            <izz>0.001</izz>
          </inertia>
          <pose>0 0 0 0 -0 0</pose>
        </inertial>
        <collision name='collision'>
          <geometry>
            <sphere>
              <radius>0.005</radius>
            </sphere>
          </geometry>
          <surface>
            <contact>
              <ode>
                <soft_cfm>0</soft_cfm>
                <soft_erp>0.2</soft_erp>
                <kp>100000</kp>
                <kd>1</kd>
                <max_vel>0.01</max_vel>
                <min_depth>0.001</min_depth>
              </ode>
            </contact>
            <bounce/>
            <friction>
              <torsional>
                <ode/>
              </torsional>
              <ode/>
            </friction>
          </surface>
          <max_contacts>10</max_contacts>
        </collision>
        <self_collide>0</self_collide>
        <enable_wind>0</enable_wind>
        <kinematic>0</kinematic>
      </link>
      <joint name='base_joint' type='fixed'>
        <parent>base_footprint</parent>
        <child>base_link</child>
        <pose>0 0 0.01 0 -0 0</pose>
      </joint>
      <joint name='wheel_left_joint' type='revolute'>
        <parent>base_link</parent>
        <child>wheel_left_link</child>
        <pose>0 0.08 0.023 -1.57 0 0</pose>
        <axis>
          <xyz>0 0 1</xyz>
          <limit>
            <lower>-1e+16</lower>
            <upper>1e+16</upper>
          </limit>
          <dynamics>
            <spring_reference>0</spring_reference>
            <spring_stiffness>0</spring_stiffness>
          </dynamics>
        </axis>
      </joint>
      <joint name='wheel_right_joint' type='revolute'>
        <parent>base_link</parent>
        <child>wheel_right_link</child>
        <pose>0 -0.08 0.023 -1.57 0 0</pose>
        <axis>
          <xyz>0 0 1</xyz>
          <limit>
            <lower>-1e+16</lower>
            <upper>1e+16</upper>
          </limit>
          <dynamics>
            <spring_reference>0</spring_reference>
            <spring_stiffness>0</spring_stiffness>
          </dynamics>
        </axis>
      </joint>
      <joint name='caster_back_joint' type='ball'>
        <parent>base_link</parent>
        <child>caster_back_link</child>
      </joint>
      <joint name='imu_joint' type='fixed'>
        <parent>base_link</parent>
        <child>imu_link</child>
        <pose>-0.032 0 0.068 0 -0 0</pose>
        <axis>
          <xyz>0 0 1</xyz>
          <limit>
            <lower>-1e+16</lower>
            <upper>1e+16</upper>
          </limit>
        </axis>
      </joint>
      <joint name='lidar_joint' type='fixed'>
        <parent>base_link</parent>
        <child>base_scan</child>
        <pose>-0.032 0 0.171 0 -0 0</pose>
        <axis>
          <xyz>0 0 1</xyz>
          <limit>
            <lower>-1e+16</lower>
            <upper>1e+16</upper>
          </limit>
        </axis>
      </joint>
      <plugin name='turtlebot3_diff_drive' filename='libgazebo_ros_diff_drive.so'>
        <ros/>
        <update_rate>30</update_rate>
        <left_joint>wheel_left_joint</left_joint>
        <right_joint>wheel_right_joint</right_joint>
        <wheel_separation>0.160</wheel_separation>
        <wheel_diameter>0.066</wheel_diameter>
        <max_wheel_torque>20</max_wheel_torque>
        <max_wheel_acceleration>1.0</max_wheel_acceleration>
        <command_topic>cmd_vel</command_topic>
        <publish_odom>1</publish_odom>
        <publish_odom_tf>1</publish_odom_tf>
        <publish_wheel_tf>0</publish_wheel_tf>
        <odometry_topic>odom</odometry_topic>
        <odometry_frame>odom</odometry_frame>
        <robot_base_frame>base_footprint</robot_base_frame>
      </plugin>
      <plugin name='turtlebot3_joint_state' filename='libgazebo_ros_joint_state_publisher.so'>
        <ros>
          <remapping>~/out:=joint_states</remapping>
        </ros>
        <update_rate>30</update_rate>
        <joint_name>wheel_left_joint</joint_name>
        <joint_name>wheel_right_joint</joint_name>
      </plugin>
    </model>
    <state world_name='default'>
      <sim_time>1302 614000000</sim_time>
      <real_time>1824 215765869</real_time>
      <wall_time>1765295514 752258849</wall_time>
      <iterations>1302614</iterations>
      <model name='Marker10'>
        <pose>1.07015 0.017252 -0.986041 3.14159 -1.5649 3.14159</pose>
        <scale>1 1 1</scale>
        <link name='link'>
          <pose>1.07015 0.017252 -0.986041 3.14159 -1.5649 3.14159</pose>
          <velocity>0 0 0 0 -0 0</velocity>
          <acceleration>0 0 0 0 -0 0</acceleration>
          <wrench>0 0 0 0 -0 0</wrench>
        </link>
      </model>
      <model name='Marker2'>
        <pose>-0.738958 -1.37783 0.015409 3.14159 -1.55803 3.14159</pose>
        <scale>1 1 1</scale>
        <link name='link'>
          <pose>-0.738958 -1.37783 0.015409 3.14159 -1.55803 3.14159</pose>
          <velocity>0 0 0 0 -0 0</velocity>
          <acceleration>0 0 0 0 -0 0</acceleration>
          <wrench>0 0 0 0 -0 0</wrench>
        </link>
      </model>
      <model name='Marker3'>
        <pose>0.341902 -0.00965 0.211111 3.14159 -1.5397 3.14159</pose>
        <scale>1 1 1</scale>
        <link name='link'>
          <pose>0.341902 -0.00965 0.211111 3.14159 -1.5397 3.14159</pose>
          <velocity>0 0 0 0 -0 0</velocity>
          <acceleration>0 0 0 0 -0 0</acceleration>
          <wrench>0 0 0 0 -0 0</wrench>
        </link>
      </model>
      <model name='eurobot_cositas'>
        <pose>0.050433 0.001506 0 0 -0 1.56945</pose>
        <scale>1 1 1</scale>
        <link name='wall_neg_x'>
          <pose>0.048414 -1.49849 0.035 0 -0 1.56945</pose>
          <velocity>0 0 0 0 -0 0</velocity>
          <acceleration>0 0 0 0 -0 0</acceleration>
          <wrench>0 0 0 0 -0 0</wrench>
        </link>
        <link name='wall_neg_y'>
          <pose>1.05043 0.00016 0.035 0 -0 1.56945</pose>
          <velocity>0 0 0 0 -0 0</velocity>
          <acceleration>0 0 0 0 -0 0</acceleration>
          <wrench>0 0 0 0 -0 0</wrench>
        </link>
        <link name='wall_pos_x'>
          <pose>0.052452 1.5015 0.035 0 -0 1.56945</pose>
          <velocity>0 0 0 0 -0 0</velocity>
          <acceleration>0 0 0 0 -0 0</acceleration>
          <wrench>0 0 0 0 -0 0</wrench>
        </link>
        <link name='wall_pos_y'>
          <pose>-0.949566 0.002852 0.035 0 -0 1.56945</pose>
          <velocity>0 0 0 0 -0 0</velocity>
          <acceleration>0 0 0 0 -0 0</acceleration>
          <wrench>0 0 0 0 -0 0</wrench>
        </link>
      </model>
      <model name='ground_plane'>
        <pose>0 0 0 0 -0 0</pose>
        <scale>1 1 1</scale>
        <link name='link'>
          <pose>0 0 0 0 -0 0</pose>
          <velocity>0 0 0 0 -0 0</velocity>
          <acceleration>0 0 0 0 -0 0</acceleration>
          <wrench>0 0 0 0 -0 0</wrench>
        </link>
      </model>
      <model name='turtlebot3_burger'>
        <pose>0.261093 -0.013943 0.008533 0.000447 0.00578 0.001089</pose>
        <scale>1 1 1</scale>
        <link name='base_footprint'>
          <pose>0.261093 -0.013943 0.008533 0.000447 0.00578 0.001089</pose>
          <velocity>-6e-06 8e-06 -0.050874 0.000429 0.000828 8e-06</velocity>
          <acceleration>-0.001089 -2e-05 0.281989 -5.3e-05 0.046522 -4e-06</acceleration>
          <wrench>-0.001089 -2e-05 0.281989 0 -0 0</wrench>
        </link>
        <link name='base_link'>
          <pose>0.261093 -0.013943 0.008533 0.000447 0.00578 0.001089</pose>
          <velocity>-6e-06 8e-06 -0.050875 0.000429 0.000828 8e-06</velocity>
          <acceleration>0.002175 -1.7e-05 0.283485 -5.4e-05 0.046524 -6e-06</acceleration>
          <wrench>0.001796 -1.4e-05 0.234083 0 -0 0</wrench>
        </link>
        <link name='base_scan'>
          <pose>0.261093 -0.013943 0.008533 0.000446 0.00578 0.001089</pose>
          <velocity>-6e-06 8e-06 -0.05087 0.000429 0.000828 8e-06</velocity>
          <acceleration>0.006411 -1.1e-05 0.282746 -5.3e-05 0.046533 -4e-06</acceleration>
          <wrench>0.000731 -1e-06 0.032233 0 -0 0</wrench>
        </link>
        <link name='caster_back_link'>
          <pose>0.180071 -0.014029 0.005001 -1.81287 -0.076772 0.012263</pose>
          <velocity>-2e-06 1.1e-05 -0.05 -0.002129 -0.000476 -0</velocity>
          <acceleration>-3.5e-05 -3e-06 0.262384 0.000522 -0.00071 0</acceleration>
          <wrench>-0 -0 0.001312 0 -0 0</wrench>
        </link>
        <link name='imu_link'>
          <pose>0.261093 -0.013943 0.008533 0.000447 0.00578 0.001089</pose>
          <velocity>-6e-06 8e-06 -0.050871 0.000429 0.000828 8e-06</velocity>
          <acceleration>-0.001087 -2e-05 0.281895 -5.4e-05 0.04652 -4e-06</acceleration>
          <wrench>-0.001087 -2e-05 0.281895 0 -0 0</wrench>
        </link>
        <link name='wheel_left_link'>
          <pose>0.259752 -0.013944 0.00858 0.000449 0.064296 0.001162</pose>
          <velocity>5e-06 -4e-06 -0.050883 0.000423 0.000394 8e-06</velocity>
          <acceleration>-6e-05 -1e-06 0.282272 3.2e-05 -0.001836 -6.6e-05</acceleration>
          <wrench>-2e-06 -0 0.008044 0 -0 0</wrench>
        </link>
        <link name='wheel_right_link'>
          <pose>0.259623 -0.013945 0.008588 0.00045 0.069561 0.001168</pose>
          <velocity>4e-06 -4e-06 -0.050883 0.000423 0.000468 8e-06</velocity>
          <acceleration>-6.2e-05 -1e-06 0.282219 3e-05 -0.001892 -6.6e-05</acceleration>
          <wrench>-2e-06 -0 0.008043 0 -0 0</wrench>
        </link>
      </model>
      <light name='sun'>
        <pose>0 0 10 0 -0 0</pose>
      </light>
    </state>
    <gui fullscreen='0'>
      <camera name='user_camera'>
        <pose>6.51745 0.175167 2.20228 0 0.275643 3.11619</pose>
        <view_controller>orbit</view_controller>
        <projection_type>perspective</projection_type>
      </camera>
    </gui>
  </world>
</sdf>
